Workbook

Sheet Dados_Principais
A1: ID_Paciente | B1: Data_Admissao | C1: Idade | D1: Genero | E1: Peso_kg | F1: Altura_cm | G1: IMC | H1: Departamento | I1: Diagnostico | J1: Pressao_Sistolica | K1: Pressao_Diastolica | L1: Glicemia_mgdl | M1: Dias_Internamento | N1: Custo_Tratamento_MT | O1: Provincia | P1: Hospital | Q1: Estado_Alta | R1: Satisfacao_1a5 | T1: Provincia | U1: Hospital_Referencia
A2: P00001 | B2: 45581 | C2: 36 | D2: Masculino | E2: 52.7 | F2: 169.3 | G2: =E2/((F2/100)^2) -> 18.3864 | H2: Cardiologia | I2: Hipertensao | J2: 116 | K2: 77 | L2: 99 | M2: 1 | N2: 3569.47 | O2: Maputo Cidade | P2: =INDEX($U$2:$U$12,MATCH(O2,$T$2:$T$12,0)) -> Hospital Central de Maputo | Q2: Alta | R2: 4 | T2: Maputo Cidade | U2: Hospital Central de Maputo
A3: P00002 | B3: 45485 | C3: 8 | D3: Feminino | E3: 18.1 | F3: 105.8 | G3: =E3/((F3/100)^2) -> 16.169896 | H3: Pediatria | I3: Malaria | J3: 94 | K3: 60 | L3: 93 | M3: 1 | N3: 3486.67 | O3: Inhambane | P3: =INDEX($U$2:$U$12,MATCH(O3,$T$2:$T$12,0)) -> Hospital Provincial de Inhambane | Q3: Alta | R3: 2 | T3: Maputo Provincia | U3: Hospital Provincial da Matola
A4: P00003 | B4: 45397 | C4: 66 | D4: Masculino | E4: 68.7 | F4: 169.6 | G4: =E4/((F4/100)^2) -> 23.883889 | H4: Doencas_Infecciosas | I4: Esquistossomose | J4: 109 | K4: 58 | L4: 85 | M4: 1 | N4: 5417.42 | O4: Niassa | P4: =INDEX($U$2:$U$12,MATCH(O4,$T$2:$T$12,0)) -> Hospital Provincial de Lichinga | Q4: Internado | R4: 5 | T4: Gaza | U4: Hospital Provincial de Xai-Xai
A5: P00004 | B5: 45316 | C5: 46 | D5: Feminino | E5: 73.6 | F5: 167.4 | G5: =E5/((F5/100)^2) -> 26.264365 | H5: Neurologia | I5: Epilepsia | J5: 109 | K5: 59 | L5: 87 | M5: 4 | N5: 9873 | O5: Sofala | P5: =INDEX($U$2:$U$12,MATCH(O5,$T$2:$T$12,0)) -> Hospital Central da Beira | Q5: Alta | R5: 5 | T5: Inhambane | U5: Hospital Provincial de Inhambane
A6: P00005 | B6: 45631 | C6: 32 | D6: Masculino | E6: 67 | F6: 163.3 | G6: =E6/((F6/100)^2) -> 25.12479 | H6: Urgencia | I6: Malaria Grave | J6: 109 | K6: 71 | L6: 99 | M6: 8 | N6: 15621.93 | O6: Sofala | P6: =INDEX($U$2:$U$12,MATCH(O6,$T$2:$T$12,0)) -> Hospital Central da Beira | Q6: Internado | R6: 4 | T6: Sofala | U6: Hospital Central da Beira
A7: P00006 | B7: 45198 | C7: 17 | D7: Masculino | E7: 63.8 | F7: 183.9 | G7: =E7/((F7/100)^2) -> 18.865018 | H7: Pediatria | I7: Pneumonia | J7: 94 | K7: 55 | L7: 79 | M7: 23 | N7: 30147.65 | O7: Zambezia | P7: =INDEX($U$2:$U$12,MATCH(O7,$T$2:$T$12,0)) -> Hospital Central de Quelimane | Q7: Internado | R7: 3 | T7: Manica | U7: Hospital Provincial de Chimoio
A8: P00007 | B8: 45090 | C8: 20 | D8: Feminino | E8: 32.6 | F8: 171 | G8: =E8/((F8/100)^2) -> 11.14873 | H8: Oncologia | I8: Linfoma | J8: 102 | K8: 63 | L8: 85 | M8: 5 | N8: 16104.28 | O8: Gaza | P8: =INDEX($U$2:$U$12,MATCH(O8,$T$2:$T$12,0)) -> Hospital Provincial de Xai-Xai | Q8: Alta | R8: 3 | T8: Tete | U8: Hospital Provincial de Tete
A9: P00008 | B9: 45372 | C9: 71 | D9: Masculino | E9: 84 | F9: 157.7 | G9: =E9/((F9/100)^2) -> 33.776598 | H9: Neurologia | I9: Epilepsia | J9: 124 | K9: 74 | L9: 92 | M9: 3 | N9: 10681.27 | O9: Maputo Provincia | P9: =INDEX($U$2:$U$12,MATCH(O9,$T$2:$T$12,0)) -> Hospital Provincial da Matola | Q9: Alta | R9: 3 | T9: Zambezia | U9: Hospital Central de Quelimane
A10: P00009 | B10: 45470 | C10: 29 | D10: Masculino | E10: 80.4 | F10: 163.3 | G10: =E10/((F10/100)^2) -> 30.149747 | H10: Oncologia | I10: Sarcoma de Kaposi | J10: 95 | K10: 58 | L10: 94 | M10: 8 | N10: 26989.4 | O10: Sofala | P10: =INDEX($U$2:$U$12,MATCH(O10,$T$2:$T$12,0)) -> Hospital Central da Beira | Q10: Alta | R10: 5 | T10: Nampula | U10: Hospital Central de Nampula
A11: P00010 | B11: 45055 | C11: 47 | D11: Masculino | E11: 90.9 | F11: 161.2 | G11: =E11/((F11/100)^2) -> 34.981128 | H11: Urgencia | I11: Trauma | J11: 112 | K11: 69 | L11: 65 | M11: 4 | N11: 9952.96 | O11: Inhambane | P11: =INDEX($U$2:$U$12,MATCH(O11,$T$2:$T$12,0)) -> Hospital Provincial de Inhambane | Q11: Internado | R11: 4 | T11: Cabo Delgado | U11: Hospital Provincial de Pemba
A12: P00011 | B12: 45180 | C12: 59 | D12: Masculino | E12: 82.8 | F12: 164.5 | G12: =E12/((F12/100)^2) -> 30.598387 | H12: Cardiologia | I12: Insuficiencia Cardiaca | J12: 124 | K12: 78 | L12: 104 | M12: 1 | N12: 3853.87 | O12: Gaza | P12: =INDEX($U$2:$U$12,MATCH(O12,$T$2:$T$12,0)) -> Hospital Provincial de Xai-Xai | Q12: Alta | R12: 4 | T12: Niassa | U12: Hospital Provincial de Lichinga
A13: P00012 | B13: 45511 | C13: 15 | D13: Feminino | E13: 69 | F13: 164.5 | G13: =E13/((F13/100)^2) -> 25.498656 | H13: Pediatria | I13: Diarreia Aguda | J13: 94 | K13: 60 | L13: 65 | M13: 4 | N13: 13559.42 | O13: Sofala | P13: =INDEX($U$2:$U$12,MATCH(O13,$T$2:$T$12,0)) -> Hospital Central da Beira | Q13: Alta | R13: 5
A14: P00013 | B14: 45181 | C14: 14 | D14: Masculino | E14: 55.4 | F14: 166 | G14: =E14/((F14/100)^2) -> 20.104514 | H14: Pediatria | I14: Desnutricao Aguda | J14: 110 | K14: 68 | L14: 128 | M14: 2 | N14: 8068.21 | O14: Maputo Cidade | P14: =INDEX($U$2:$U$12,MATCH(O14,$T$2:$T$12,0)) -> Hospital Central de Maputo | Q14: Transferido | R14: 5
A15: P00014 | B15: 45022 | C15: 15 | D15: Masculino | E15: 75.8 | F15: 165.1 | G15: =E15/((F15/100)^2) -> 27.80834 | H15: Pediatria | I15: Diarreia Aguda | J15: 116 | K15: 74 | L15: 101 | M15: 6 | N15: 13590.44 | O15: Cabo Delgado | P15: =INDEX($U$2:$U$12,MATCH(O15,$T$2:$T$12,0)) -> Hospital Provincial de Pemba | Q15: Transferido | R15: 4
A16: P00015 | B16: 45425 | C16: 6 | D16: Masculino | E16: 13 | F16: 103.3 | G16: =E16/((F16/100)^2) -> 12.182676 | H16: Pediatria | I16: Malaria | J16: 95 | K16: 58 | L16: 80 | M16: 3 | N16: 9413.1 | O16: Maputo Provincia | P16: =INDEX($U$2:$U$12,MATCH(O16,$T$2:$T$12,0)) -> Hospital Provincial da Matola | Q16: Transferido | R16: 2
A17: P00016 | B17: 45117 | C17: 32 | D17: Masculino | E17: 78.5 | F17: 157.1 | G17: =E17/((F17/100)^2) -> 31.806603 | H17: Oncologia | I17: Cancro do Colo do Utero | J17: 107 | K17: 64 | L17: 86 | M17: 1 | N17: 6264.16 | O17: Inhambane | P17: =INDEX($U$2:$U$12,MATCH(O17,$T$2:$T$12,0)) -> Hospital Provincial de Inhambane | Q17: Alta | R17: 4
A18: P00017 | B18: 45248 | C18: 4 | D18: Masculino | E18: 30.1 | F18: 51.8 | G18: =E18/((F18/100)^2) -> 112.17781 | H18: Pediatria | I18: Pneumonia | J18: 103 | K18: 63 | L18: 69 | M18: 1 | N18: 4304.8 | O18: Maputo Cidade | P18: =INDEX($U$2:$U$12,MATCH(O18,$T$2:$T$12,0)) -> Hospital Central de Maputo | Q18: Alta | R18: 2
A19: P00018 | B19: 45177 | C19: 14 | D19: Feminino | E19: 36.9 | F19: 155 | G19: =E19/((F19/100)^2) -> 15.359001 | H19: Pediatria | I19: Pneumonia | J19: 85 | K19: 55 | L19: 85 | M19: 6 | N19: 12187.93 | O19: Cabo Delgado | P19: =INDEX($U$2:$U$12,MATCH(O19,$T$2:$T$12,0)) -> Hospital Provincial de Pemba | Q19: Alta | R19: 3
A20: P00019 | B20: 45036 | C20: 6 | D20: Masculino | E20: 37.6 | F20: 114.8 | G20: =E20/((F20/100)^2) -> 28.530151 | H20: Pediatria | I20: Pneumonia | J20: 101 | K20: 69 | L20: 115 | M20: 1 | N20: 3331.93 | O20: Maputo Cidade | P20: =INDEX($U$2:$U$12,MATCH(O20,$T$2:$T$12,0)) -> Hospital Central de Maputo | Q20: Alta | R20: 4
A21: P00020 | B21: 45195 | C21: 19 | D21: Masculino | E21: 61.8 | F21: 158.9 | G21: =E21/((F21/100)^2) -> 24.476013 | H21: Urgencia | I21: Trauma | J21: 124 | K21: 73 | L21: 90 | M21: 1 | N21: 4103.15 | O21: Maputo Cidade | P21: =INDEX($U$2:$U$12,MATCH(O21,$T$2:$T$12,0)) -> Hospital Central de Maputo | Q21: Alta | R21: 5
A22: P00021 | B22: 44967 | C22: 7 | D22: Feminino | E22: 16.2 | F22: 110.2 | G22: =E22/((F22/100)^2) -> 13.339877 | H22: Pediatria | I22: Malaria | J22: 115 | K22: 82 | L22: 65 | M22: 5 | N22: 16480.17 | O22: Maputo Provincia | P22: =INDEX($U$2:$U$12,MATCH(O22,$T$2:$T$12,0)) -> Hospital Provincial da Matola | Q22: Internado | R22: 3
A23: P00022 | B23: 45349 | C23: 10 | D23: Masculino | E23: 5.1 | F23: 120.5 | G23: =E23/((F23/100)^2) -> 3.5123362 | H23: Pediatria | I23: Diarreia Aguda | J23: 107 | K23: 61 | L23: 89 | M23: 8 | N23: 24287.66 | O23: Nampula | P23: =INDEX($U$2:$U$12,MATCH(O23,$T$2:$T$12,0)) -> Hospital Central de Nampula | Q23: Alta | R23: 4
A24: P00023 | B24: 45160 | C24: 30 | D24: Masculino | E24: 69.8 | F24: 157.2 | G24: =E24/((F24/100)^2) -> 28.24557 | H24: Cardiologia | I24: Insuficiencia Cardiaca | J24: 130 | K24: 84 | L24: 86 | M24: 4 | N24: 12988.25 | O24: Maputo Cidade | P24: =INDEX($U$2:$U$12,MATCH(O24,$T$2:$T$12,0)) -> Hospital Central de Maputo | Q24: Internado | R24: 3
... A1501: P01500 | B1501: 45055 | C1501: 39 | D1501: Masculino | E1501: 84.3 | F1501: 156.6 | G1501: =E1501/((F1501/100)^2) -> 34.375107 | H1501: Urgencia | I1501: Colera | J1501: 109 | K1501: 55 | L1501: 97 | M1501: 11 | N1501: 16157.97 | O1501: Manica | P1501: =INDEX($U$2:$U$12,MATCH(O1501,$T$2:$T$12,0)) -> Hospital Provincial de Chimoio | Q1501: Alta | R1501: 3

Sheet Barras_Coluna
A1: Departamento | B1: Numero_Casos | C1: Custo_Medio_MT | D1: Dias_Internamento_Medio

Sheet Pizza_Rosca
A1: Regiao | B1: Numero_Casos | C1: Percentagem

Sheet Linha_Area
A1: Ano | B1: Mes | C1: Numero_Admissoes | D1: Custo_Total_MT

Sheet Dispersao_Bolhas
A1: ID_Paciente | B1: Peso_kg | C1: Altura_cm | D1: IMC
A2: =Dados_Principais!A2 -> P00001
A3: =Dados_Principais!A27 -> P00026
A4: =Dados_Principais!A52 -> P00051
A5: =Dados_Principais!A77 -> P00076
A6: =Dados_Principais!A102 -> P00101
A7: =Dados_Principais!A127 -> P00126
A8: =Dados_Principais!A152 -> P00151
A9: =Dados_Principais!A177 -> P00176
A10: =Dados_Principais!A202 -> P00201
A11: =Dados_Principais!A227 -> P00226
A12: =Dados_Principais!A252 -> P00251
A13: =Dados_Principais!A277 -> P00276
A14: =Dados_Principais!A302 -> P00301
A15: =Dados_Principais!A327 -> P00326
A16: =Dados_Principais!A352 -> P00351
A17: =Dados_Principais!A377 -> P00376
A18: =Dados_Principais!A402 -> P00401
A19: =Dados_Principais!A427 -> P00426
A20: =Dados_Principais!A452 -> P00451
A21: =Dados_Principais!A477 -> P00476
A22: =Dados_Principais!A502 -> P00501
A23: =Dados_Principais!A527 -> P00526
A24: =Dados_Principais!A552 -> P00551
A25: =Dados_Principais!A577 -> P00576
A26: =Dados_Principais!A602 -> P00601
A27: =Dados_Principais!A627 -> P00626
A28: =Dados_Principais!A652 -> P00651
A29: =Dados_Principais!A677 -> P00676
A30: =Dados_Principais!A702 -> P00701
A31: =Dados_Principais!A727 -> P00726
A32: =Dados_Principais!A752 -> P00751
A33: =Dados_Principais!A777 -> P00776
A34: =Dados_Principais!A802 -> P00801
A35: =Dados_Principais!A827 -> P00826
A36: =Dados_Principais!A852 -> P00851
A37: =Dados_Principais!A877 -> P00876
A38: =Dados_Principais!A902 -> P00901
A39: =Dados_Principais!A927 -> P00926
A40: =Dados_Principais!A952 -> P00951
...

Sheet Histograma
A1: ID_Paciente | B1: Idade_Anos | C1: Glicemia_mgdl
A2: P00001
A3: P00002
A4: P00003
A5: P00004
A6: P00005
A7: P00006
A8: P00007
A9: P00008
A10: P00009
A11: P00010
A12: P00011
A13: P00012
... A1501: P01500

Sheet BoxPlot
A1: ID_Paciente | B1: Departamento | C1: Pressao_Sistolica
A2: P00001
A3: P00002
A4: P00003
A5: P00004
A6: P00005
A7: P00006
A8: P00007
A9: P00008
A10: P00009
A11: P00010
A12: P00011
A13: P00012
... A1501: P01500
